Workbook

Sheet Resumen
A1: Inventario de fuentes · Hackathon 2026
A2: Construido desde data/seed_targets.json y los legal_basis de data/sample_50.jsonl. Los conteos son fórmulas sobre las hojas de cada área y el inventario completo.
A4: Área | B4: Preguntas | C4: Docs en seed | D4: Faltan · alta | E4: Faltan · media | F4: Faltan · baja | G4: Cobertura estimada del seed | H4: Normas de muestra sin cubrir
A5: Constitucional | B5: 134 | C5: =COUNTIFS(Constitucional!$F:$F,"en seed*") -> 43 | D5: =COUNTIFS(Constitucional!$F:$F,"falta*",Constitucional!$G:$G,"alta") -> 6 | E5: =COUNTIFS(Constitucional!$F:$F,"falta*",Constitucional!$G:$G,"media") -> 16 | F5: =COUNTIFS(Constitucional!$F:$F,"falta*",Constitucional!$G:$G,"baja") -> 1 | G5: 0.55 | H5: 4
A6: Administrativo | B6: 124 | C6: =COUNTIFS(Administrativo!$F:$F,"en seed*") -> 18 | D6: =COUNTIFS(Administrativo!$F:$F,"falta*",Administrativo!$G:$G,"alta") -> 4 | E6: =COUNTIFS(Administrativo!$F:$F,"falta*",Administrativo!$G:$G,"media") -> 14 | F6: =COUNTIFS(Administrativo!$F:$F,"falta*",Administrativo!$G:$G,"baja") -> 4 | G6: 0.31 | H6: 4
A7: Penal | B7: 123 | C7: =COUNTIFS(Penal!$F:$F,"en seed*") -> 18 | D7: =COUNTIFS(Penal!$F:$F,"falta*",Penal!$G:$G,"alta") -> 2 | E7: =COUNTIFS(Penal!$F:$F,"falta*",Penal!$G:$G,"media") -> 10 | F7: =COUNTIFS(Penal!$F:$F,"falta*",Penal!$G:$G,"baja") -> 4 | G7: 0.33 | H7: 3
A8: Procesal | B8: 111 | C8: =COUNTIFS(Procesal!$F:$F,"en seed*") -> 10 | D8: =COUNTIFS(Procesal!$F:$F,"falta*",Procesal!$G:$G,"alta") -> 4 | E8: =COUNTIFS(Procesal!$F:$F,"falta*",Procesal!$G:$G,"media") -> 5 | F8: =COUNTIFS(Procesal!$F:$F,"falta*",Procesal!$G:$G,"baja") -> 2 | G8: 0.32 | H8: 1
A9: Comercial | B9: 104 | C9: =COUNTIFS(Comercial!$F:$F,"en seed*") -> 20 | D9: =COUNTIFS(Comercial!$F:$F,"falta*",Comercial!$G:$G,"alta") -> 3 | E9: =COUNTIFS(Comercial!$F:$F,"falta*",Comercial!$G:$G,"media") -> 4 | F9: =COUNTIFS(Comercial!$F:$F,"falta*",Comercial!$G:$G,"baja") -> 4 | G9: 0.51 | H9: 4
A10: Civil | B10: 102 | C10: =COUNTIFS(Civil!$F:$F,"en seed*") -> 24 | D10: =COUNTIFS(Civil!$F:$F,"falta*",Civil!$G:$G,"alta") -> 2 | E10: =COUNTIFS(Civil!$F:$F,"falta*",Civil!$G:$G,"media") -> 4 | F10: =COUNTIFS(Civil!$F:$F,"falta*",Civil!$G:$G,"baja") -> 3 | G10: 0.55 | H10: 3
A11: Familia | B11: 93 | C11: =COUNTIFS(Familia!$F:$F,"en seed*") -> 29 | D11: =COUNTIFS(Familia!$F:$F,"falta*",Familia!$G:$G,"alta") -> 1 | E11: =COUNTIFS(Familia!$F:$F,"falta*",Familia!$G:$G,"media") -> 9 | F11: =COUNTIFS(Familia!$F:$F,"falta*",Familia!$G:$G,"baja") -> 4 | G11: 0.62 | H11: 4
A12: Tributario | B12: 92 | C12: =COUNTIFS(Tributario!$F:$F,"en seed*") -> 19 | D12: =COUNTIFS(Tributario!$F:$F,"falta*",Tributario!$G:$G,"alta") -> 2 | E12: =COUNTIFS(Tributario!$F:$F,"falta*",Tributario!$G:$G,"media") -> 7 | F12: =COUNTIFS(Tributario!$F:$F,"falta*",Tributario!$G:$G,"baja") -> 3 | G12: 0.55 | H12: 2
A13: Laboral | B13: 87 | C13: =COUNTIFS(Laboral!$F:$F,"en seed*") -> 30 | D13: =COUNTIFS(Laboral!$F:$F,"falta*",Laboral!$G:$G,"alta") -> 1 | E13: =COUNTIFS(Laboral!$F:$F,"falta*",Laboral!$G:$G,"media") -> 12 | F13: =COUNTIFS(Laboral!$F:$F,"falta*",Laboral!$G:$G,"baja") -> 5 | G13: 1.06 | H13: 0
A14: Mercados | B14: 72 | C14: =COUNTIFS(Mercados!$F:$F,"en seed*") -> 15 | D14: =COUNTIFS(Mercados!$F:$F,"falta*",Mercados!$G:$G,"alta") -> 3 | E14: =COUNTIFS(Mercados!$F:$F,"falta*",Mercados!$G:$G,"media") -> 5 | F14: =COUNTIFS(Mercados!$F:$F,"falta*",Mercados!$G:$G,"baja") -> 4 | G14: 0.85 | H14: 1
A15: Total | B15: =SUM(B5:B14) -> 1042 | C15: =SUM(C5:C14) -> 226 | D15: =SUM(D5:D14) -> 28 | E15: =SUM(E5:E14) -> 86 | F15: =SUM(F5:F14) -> 34
A16: Los totales por área suman documentos compartidos más de una vez; los conteos únicos están abajo.
A18: Documentos únicos
A19: Documentos en el seed | B19: =COUNTIFS('Inventario completo'!$F:$F,"en seed*") -> 186
A20: de ellos, marcados para revisar | B20: =COUNTIFS('Inventario completo'!$F:$F,"en seed · revisar") -> 8
A21: Faltantes · prioridad alta | B21: =COUNTIFS('Inventario completo'!$F:$F,"falta*",'Inventario completo'!$G:$G,"alta") -> 23
A22: Faltantes · prioridad media | B22: =COUNTIFS('Inventario completo'!$F:$F,"falta*",'Inventario completo'!$G:$G,"media") -> 79
A23: Faltantes · prioridad baja | B23: =COUNTIFS('Inventario completo'!$F:$F,"falta*",'Inventario completo'!$G:$G,"baja") -> 33
A24: Faltantes · total | B24: =SUM(B21:B23) -> 135
A25: de ellos, por verificar | B25: =COUNTIFS('Inventario completo'!$F:$F,"falta · por verificar") -> 14
A28: Las 3 áreas con mayor brecha
A29: 1. Administrativo (124 preguntas): cobertura estimada 0,31. Falta su norma base (CPACA, citado 2 veces en la muestra), la Ley 472 de 1998 y la Ley 489 de 1998.
A30: 2. Procesal (111 preguntas): cobertura estimada 0,32. Tiene el CGP pero le faltan el CPACA, el CPP, la Ley 270 de 1996 y el Código Procesal del Trabajo anterior.
A31: 3. Penal (123 preguntas): cobertura estimada 0,33. No tiene ni el Código Penal (3 citas en la muestra) ni el CPP; el seed solo trae jurisprudencia penal.
A32: Juntas suman 358 preguntas (34% del banco). Siguen Comercial (0,51, sin Código de Comercio) y Civil/Familia (sin Código Civil, 5 citas en la muestra).
A34: Criterios y convenciones
A35: Prioridad alta: norma base del área, citada en un legal_basis de muestra, o (en el seed) citada en 5 o más ítems del banco.
A36: Prioridad media: complementaria de uso frecuente, sentencia de unificación o hito, o (en el seed) 2 a 4 ítems. Baja: cobertura marginal o 1 ítem.
A37: En las áreas con más preguntas (constitucional, administrativo, penal) las complementarias de uso amplio se subieron a media.
A38: URL del seed: se conservan tal cual (son puntos de búsqueda con ?q=). URL de faltantes: códigos con página verificada en el Senado; leyes con el patrón verificado basedoc/ley_NNNN_AAAA.html (confirmar al descargar); decretos con búsqueda en SUIN; sentencias con búsqueda en la relatoría.
A39: Documentos compartidos entre áreas (p. ej., Código Civil, CPACA, CPP) aparecen en cada hoja de área y una sola vez en 'Inventario completo'.
A40: Las sentencias de la Corte Suprema (SC, SL, SP) del seed apuntan a la relatoría de la Corte Constitucional: hay que buscarlas en la de la Corte Suprema.

Sheet Constitucional
A1: Constitucional · 134 preguntas en el banco
A2: Estados: 'en seed' = viene en seed_targets.json · 'falta' = hay que agregarlo · 'por verificar' = confirmar número, año o URL antes de descargar.
A4: doc_id | B4: título | C4: tipo | D4: fuente | E4: URL | F4: estado | G4: prioridad | H4: justificación
A5: EN EL SEED (43 documentos)
A6: constitucion_1991 | B6: Constitución Política de 1991 | C6: constitución | D6: Secretaría del Senado | E6: http://www.secretariasenado.gov.co/senado/basedoc/constitucion_politica_1991.html?q=Constitucion | F6: en seed | G6: alta | H6: Norma más citada del banco. Jerarquía, existencia normativa, ponderación y conflicto normativo en todas las áreas. Citada en 90 ítem(s) del banco según el seed. En legal_basis de muestra (ids 51, 60, 218, 661, 1005, 1073).
A7: decreto_624_1989 | B7: Estatuto Tributario (Decreto 624 de 1989) | C7: código | D7: Secretaría del Senado | E7: http://www.secretariasenado.gov.co/senado/basedoc/?q=Estatuto%20tributario | F7: en seed | G7: alta | H7: Definiciones, requisitos y vigencia temporal en tributario. Citada en 35 ítem(s) del banco según el seed.
A8: sentencia_c-355_2006 | B8: Sentencia C-355 de 2006 · Corte Constitucional · despenalización parcial del aborto | C8: sentencia | D8: Relatoría Corte Constitucional | E8: https://www.corteconstitucional.gov.co/relatoria/?q=Sentencia%20C-355%20de%202006 | F8: en seed | G8: alta | H8: Citada en 7 ítem(s) del banco según el seed. En legal_basis de muestra (ids 1015).
A9: ley_1581_2012 | B9: Ley 1581 de 2012 (protección de datos personales) | C9: ley | D9: SUIN-Juriscol | E9: https://www.suin-juriscol.gov.co/legislacion/?q=Ley%201581%20de%202012 | F9: en seed | G9: alta | H9: Citada en 6 ítem(s) del banco según el seed. En legal_basis de muestra (ids 679).
A10: decreto_2067_1991 | B10: Decreto 2067 de 1991 (procedimiento ante la Corte Constitucional) | C10: decreto | D10: SUIN-Juriscol | E10: https://www.suin-juriscol.gov.co/legislacion/?q=Decreto%202067%20de%201991 | F10: en seed | G10: alta | H10: Citada en 1 ítem(s) del banco según el seed. En legal_basis de muestra (ids 352).
A11: sentencia_c-332_2025 | B11: Sentencia C-332 de 2025 · Corte Constitucional | C11: sentencia | D11: Relatoría Corte Constitucional | E11: https://www.corteconstitucional.gov.co/relatoria/?q=Sentencia%20C-332%20de%202025 | F11: en seed | G11: alta | H11: Citada en 1 ítem(s) del banco según el seed. En legal_basis de muestra (ids 453).
A12: sentencia_t-323_2024 | B12: Sentencia T-323 de 2024 · Corte Constitucional | C12: sentencia | D12: Relatoría Corte Constitucional | E12: https://www.corteconstitucional.gov.co/relatoria/?q=Sentencia%20T-323%20de%202024 | F12: en seed | G12: media | H12: Citada en 4 ítem(s) del banco según el seed.
A13: sentencia_c-055_2022 | B13: Sentencia C-55 de 2022 · Corte Constitucional | C13: sentencia | D13: Relatoría Corte Constitucional | E13: https://www.corteconstitucional.gov.co/relatoria/?q=Sentencia%20C-55%20de%202022 | F13: en seed | G13: media | H13: Citada en 3 ítem(s) del banco según el seed.
A14: sentencia_c-394_2017 | B14: Sentencia C-394 de 2017 · Corte Constitucional | C14: sentencia | D14: Relatoría Corte Constitucional | E14: https://www.corteconstitucional.gov.co/relatoria/?q=Sentencia%20C-394%20de%202017 | F14: en seed | G14: media | H14: Citada en 3 ítem(s) del banco según el seed.
A15: sentencia_t-760_2008 | B15: Sentencia T-760 de 2008 · Corte Constitucional · derecho fundamental a la salud | C15: sentencia | D15: Relatoría Corte Constitucional | E15: https://www.corteconstitucional.gov.co/relatoria/?q=Sentencia%20T-760%20de%202008 | F15: en seed | G15: media | H15: Citada en 3 ítem(s) del banco según el seed.
A16: ley_1095_2006 | B16: Ley 1095 de 2006 (hábeas corpus) | C16: ley | D16: SUIN-Juriscol | E16: https://www.suin-juriscol.gov.co/legislacion/?q=Ley%201095%20de%202006 | F16: en seed | G16: media | H16: Citada en 2 ítem(s) del banco según el seed.
A17: ley_2141_2021 | B17: Ley 2141 de 2021 | C17: ley | D17: SUIN-Juriscol | E17: https://www.suin-juriscol.gov.co/legislacion/?q=Ley%202141%20de%202021 | F17: en seed | G17: media | H17: Citada en 2 ítem(s) del banco según el seed.
... A48: sentencia_t-970_2014 | B48: Sentencia T-970 de 2014 · Corte Constitucional | C48: sentencia | D48: Relatoría Corte Constitucional | E48: https://www.corteconstitucional.gov.co/relatoria/?q=Sentencia%20T-970%20de%202014 | F48: en seed | G48: baja | H48: Citada en 1 ítem(s) del banco según el seed.
A49: FALTAN · NORMAS BASE (3)
A50: decreto_2591_1991 | B50: Acción de tutela (Decreto 2591 de 1991) | C50: decreto | D50: Secretaría del Senado | E50: http://www.secretariasenado.gov.co/senado/basedoc/decreto_2591_1991.html | F50: falta | G50: alta | H50: Norma base de la tutela: juez competente, requisitos, términos y efectos; sustento de la mayoría de sentencias T y SU del banco.
A51: ley_270_1996 | B51: Ley Estatutaria de la Administración de Justicia (Ley 270 de 1996) | C51: ley | D51: Secretaría del Senado | E51: http://www.secretariasenado.gov.co/senado/basedoc/ley_0270_1996.html | F51: falta | G51: alta | H51: Estructura de la Rama Judicial, jerarquía y competencias; sub-tareas autoridad competente y juez que decide.
A52: ley_472_1998 | B52: Acciones populares y de grupo (Ley 472 de 1998) | C52: ley | D52: Secretaría del Senado | E52: http://www.secretariasenado.gov.co/senado/basedoc/ley_0472_1998.html | F52: falta | G52: alta | H52: Citada en legal_basis de muestra (id 51). Acciones populares y derechos colectivos (art. 88 CP).
A53: FALTAN · NORMAS COMPLEMENTARIAS (8)
A54: decreto_333_2021 | B54: Reglas de reparto de la acción de tutela (Decreto 333 de 2021) | C54: decreto | D54: SUIN-Juriscol | E54: https://www.suin-juriscol.gov.co/legislacion/?q=Decreto%20333%20de%202021 | F54: falta | G54: media | H54: Juez que decide: reparto de tutelas por tipo de accionado.
A55: ley_134_1994 | B55: Mecanismos de participación ciudadana (Ley 134 de 1994) | C55: ley | D55: Secretaría del Senado | E55: http://www.secretariasenado.gov.co/senado/basedoc/ley_0134_1994.html | F55: falta | G55: media | H55: Referendo, consulta, revocatoria; existencia normativa y requisitos.
A56: ley_1712_2014 | B56: Transparencia y acceso a la información pública (Ley 1712 de 2014) | C56: ley | D56: Secretaría del Senado | E56: http://www.secretariasenado.gov.co/senado/basedoc/ley_1712_2014.html | F56: falta | G56: media | H56: Derecho de acceso a información; también administrativo.
A57: ley_1751_2015 | B57: Estatutaria del derecho fundamental a la salud (Ley 1751 de 2015) | C57: ley | D57: Secretaría del Senado | E57: http://www.secretariasenado.gov.co/senado/basedoc/ley_1751_2015.html | F57: falta | G57: media | H57: Complementa la T-760 de 2008 (en el seed); tutela en salud.
A58: ley_1757_2015 | B58: Estatutaria de participación democrática (Ley 1757 de 2015) | C58: ley | D58: Secretaría del Senado | E58: http://www.secretariasenado.gov.co/senado/basedoc/ley_1757_2015.html | F58: falta | G58: media | H58: Mecanismos de participación ciudadana; complementa la Ley 134 de 1994.
A59: ley_393_1997 | B59: Acción de cumplimiento (Ley 393 de 1997) | C59: ley | D59: Secretaría del Senado | E59: http://www.secretariasenado.gov.co/senado/basedoc/ley_0393_1997.html | F59: falta | G59: media | H59: Mecanismo constitucional (art. 87 CP); existencia normativa y requisitos.
A60: ley_5_1992 | B60: Reglamento del Congreso (Ley 5 de 1992) | C60: ley | D60: Secretaría del Senado | E60: http://www.secretariasenado.gov.co/senado/basedoc/ley_0005_1992.html | F60: falta | G60: media | H60: Trámite legislativo y vicios de procedimiento (p. ej., control de la reforma pensional).
A61: decreto_306_1992 | B61: Reglamentario del Decreto 2591 de 1991 (Decreto 306 de 1992) | C61: decreto | D61: SUIN-Juriscol | E61: https://www.suin-juriscol.gov.co/legislacion/?q=Decreto%20306%20de%201992 | F61: falta | G61: baja | H61: Reglamentación de la tutela.
A62: FALTAN · JURISPRUDENCIA (12)
A63: sentencia_c-468_2024 | B63: Sentencia C-468 de 2024 · citada en la muestra | C63: sentencia | D63: Relatoría Corte Constitucional | E63: https://www.corteconstitucional.gov.co/relatoria/?q=Sentencia%20C-468%20de%202024 | F63: falta | G63: alta | H63: Citada en legal_basis de muestra (id 453).
A64: sentencia_su-016_2020 | B64: Sentencia SU-016 de 2020 · citada en la muestra | C64: sentencia | D64: Relatoría Corte Constitucional | E64: https://www.corteconstitucional.gov.co/relatoria/?q=Sentencia%20SU-016%20de%202020 | F64: falta | G64: alta | H64: Citada en legal_basis de muestra (id 453, como SU-016 de 2020).
A65: sentencia_t-256_2025 | B65: Sentencia T-256 de 2025 · nombrada en la pregunta de muestra | C65: sentencia | D65: Relatoría Corte Constitucional | E65: https://www.corteconstitucional.gov.co/relatoria/?q=Sentencia%20T-256%20de%202025 | F65: falta | G65: alta | H65: Muestra id 190 (la pregunta la nombra; el legal_basis omite el año). Sub-tarea antecedentes fácticos.
A66: sentencia_c-093_2001 | B66: Sentencia C-093 de 2001 · juicio integrado de igualdad | C66: sentencia | D66: Relatoría Corte Constitucional | E66: https://www.corteconstitucional.gov.co/relatoria/?q=Sentencia%20C-093%20de%202001 | F66: falta · por verificar | G66: media | H66: Test de igualdad; ponderación.
A67: sentencia_c-141_2010 | B67: Sentencia C-141 de 2010 · segunda reelección presidencial y sustitución | C67: sentencia | D67: Relatoría Corte Constitucional | E67: https://www.corteconstitucional.gov.co/relatoria/?q=Sentencia%20C-141%20de%202010 | F67: falta | G67: media | H67: Juicio de sustitución; conflicto normativo.
A68: sentencia_c-551_2003 | B68: Sentencia C-551 de 2003 · control del referendo y límites al poder de reforma | C68: sentencia | D68: Relatoría Corte Constitucional | E68: https://www.corteconstitucional.gov.co/relatoria/?q=Sentencia%20C-551%20de%202003 | F68: falta | G68: media | H68: Juicio de sustitución de la Constitución.
A69: sentencia_c-590_2005 | B69: Sentencia C-590 de 2005 · causales de procedencia de la tutela contra providencias judiciales | C69: sentencia | D69: Relatoría Corte Constitucional | E69: https://www.corteconstitucional.gov.co/relatoria/?q=Sentencia%20C-590%20de%202005 | F69: falta | G69: media | H69: Hito: requisitos generales y especiales de la tutela contra sentencias; sub-tareas juez que decide y precedente.
A70: sentencia_c-836_2001 | B70: Sentencia C-836 de 2001 · doctrina probable y valor del precedente | C70: sentencia | D70: Relatoría Corte Constitucional | E70: https://www.corteconstitucional.gov.co/relatoria/?q=Sentencia%20C-836%20de%202001 | F70: falta | G70: media | H70: Sub-tarea precedente jurisprudencial.
A71: sentencia_su-047_1999 | B71: Sentencia SU-047 de 1999 · ratio decidendi y obiter dicta | C71: sentencia | D71: Relatoría Corte Constitucional | E71: https://www.corteconstitucional.gov.co/relatoria/?q=Sentencia%20SU-047%20de%201999 | F71: falta | G71: media | H71: Sub-tarea precedente jurisprudencial.
...

Sheet Administrativo
A1: Administrativo · 124 preguntas en el banco
A2: Estados: 'en seed' = viene en seed_targets.json · 'falta' = hay que agregarlo · 'por verificar' = confirmar número, año o URL antes de descargar.
A4: doc_id | B4: título | C4: tipo | D4: fuente | E4: URL | F4: estado | G4: prioridad | H4: justificación
A5: EN EL SEED (18 documentos)
A6: constitucion_1991 | B6: Constitución Política de 1991 | C6: constitución | D6: Secretaría del Senado | E6: http://www.secretariasenado.gov.co/senado/basedoc/constitucion_politica_1991.html?q=Constitucion | F6: en seed | G6: alta | H6: Norma más citada del banco. Jerarquía, existencia normativa, ponderación y conflicto normativo en todas las áreas. Citada en 90 ítem(s) del banco según el seed. En legal_basis de muestra (ids 51, 60, 218, 661, 1005, 1073).
A7: ley_80_1993 | B7: Ley 80 de 1993 (Estatuto General de Contratación) | C7: ley | D7: SUIN-Juriscol | E7: https://www.suin-juriscol.gov.co/legislacion/?q=Ley%2080%20de%201993 | F7: en seed | G7: alta | H7: Citada en 12 ítem(s) del banco según el seed.
A8: ley_1581_2012 | B8: Ley 1581 de 2012 (protección de datos personales) | C8: ley | D8: SUIN-Juriscol | E8: https://www.suin-juriscol.gov.co/legislacion/?q=Ley%201581%20de%202012 | F8: en seed | G8: alta | H8: Citada en 6 ítem(s) del banco según el seed. En legal_basis de muestra (ids 679).
A9: ley_1150_2007 | B9: Ley 1150 de 2007 (reforma a la contratación estatal) | C9: ley | D9: SUIN-Juriscol | E9: https://www.suin-juriscol.gov.co/legislacion/?q=Ley%201150%20de%202007 | F9: en seed | G9: alta | H9: Citada en 3 ítem(s) del banco según el seed. En legal_basis de muestra (ids 290).
A10: decreto_1082_2015 | B10: Decreto 1082 de 2015 (Decreto Único del sector Planeación (contratación)) | C10: decreto | D10: SUIN-Juriscol | E10: https://www.suin-juriscol.gov.co/legislacion/?q=Decreto%201082%20de%202015 | F10: en seed | G10: alta | H10: Citada en 1 ítem(s) del banco según el seed.
A11: ley_1755_2015 | B11: Ley 1755 de 2015 (derecho de petición) | C11: ley | D11: SUIN-Juriscol | E11: https://www.suin-juriscol.gov.co/legislacion/?q=Ley%201755%20de%202015 | F11: en seed | G11: alta | H11: Citada en 1 ítem(s) del banco según el seed.
A12: ley_1952_2019 | B12: Código General Disciplinario (Ley 1952 de 2019) | C12: código | D12: Secretaría del Senado | E12: http://www.secretariasenado.gov.co/senado/basedoc/?q=Codigo%20disciplinario | F12: en seed | G12: alta | H12: Se asume el Código General Disciplinario vigente (Ley 1952 de 2019); confirmar versión. Citada en 1 ítem(s) del banco según el seed.
A13: sentencia_c-207_2019 | B13: Sentencia C-207 de 2019 · Corte Constitucional | C13: sentencia | D13: Relatoría Corte Constitucional | E13: https://www.corteconstitucional.gov.co/relatoria/?q=Sentencia%20C-207%20de%202019 | F13: en seed | G13: media | H13: Citada en 4 ítem(s) del banco según el seed.
A14: sentencia_t-760_2008 | B14: Sentencia T-760 de 2008 · Corte Constitucional · derecho fundamental a la salud | C14: sentencia | D14: Relatoría Corte Constitucional | E14: https://www.corteconstitucional.gov.co/relatoria/?q=Sentencia%20T-760%20de%202008 | F14: en seed | G14: media | H14: Citada en 3 ítem(s) del banco según el seed.
A15: sentencia_c-259_2015 | B15: Sentencia C-259 de 2015 · Corte Constitucional | C15: sentencia | D15: Relatoría Corte Constitucional | E15: https://www.corteconstitucional.gov.co/relatoria/?q=Sentencia%20C-259%20de%202015 | F15: en seed | G15: media | H15: Citada en 2 ítem(s) del banco según el seed.
A16: sentencia_su-011_2020 | B16: Sentencia SU-11 de 2020 · Corte Constitucional | C16: sentencia | D16: Relatoría Corte Constitucional | E16: https://www.corteconstitucional.gov.co/relatoria/?q=Sentencia%20SU-11%20de%202020 | F16: en seed | G16: media | H16: Citada en 1 ítem(s) del banco según el seed.
A17: sentencia_su-240_2015 | B17: Sentencia SU-240 de 2015 · Corte Constitucional | C17: sentencia | D17: Relatoría Corte Constitucional | E17: https://www.corteconstitucional.gov.co/relatoria/?q=Sentencia%20SU-240%20de%202015 | F17: en seed | G17: media | H17: Citada en 1 ítem(s) del banco según el seed.
... A23: sentencia_su-006_1991 | B23: Sentencia SU-6 de 1991 · Corte Constitucional | C23: sentencia | D23: Relatoría Corte Constitucional | E23: https://www.corteconstitucional.gov.co/relatoria/?q=Sentencia%20SU-6%20de%201991 | F23: en seed · revisar | G23: baja | H23: Citada en 1 ítem(s) del banco según el seed. La Corte Constitucional empezó a fallar en 1992: número o año por verificar.
A24: FALTAN · NORMAS BASE (3)
A25: ley_1437_2011 | B25: Código de Procedimiento Administrativo y de lo Contencioso Administrativo (CPACA, Ley 1437 de 2011) | C25: ley | D25: Secretaría del Senado | E25: http://www.secretariasenado.gov.co/senado/basedoc/ley_1437_2011.html | F25: falta | G25: alta | H25: Citado en legal_basis de muestra (id 748). Procedimiento administrativo, medios de control y jurisdicción contenciosa.
A26: ley_472_1998 | B26: Acciones populares y de grupo (Ley 472 de 1998) | C26: ley | D26: Secretaría del Senado | E26: http://www.secretariasenado.gov.co/senado/basedoc/ley_0472_1998.html | F26: falta | G26: alta | H26: Citada en legal_basis de muestra (id 247).
A27: ley_489_1998 | B27: Organización y funcionamiento de la administración pública (Ley 489 de 1998) | C27: ley | D27: Secretaría del Senado | E27: http://www.secretariasenado.gov.co/senado/basedoc/ley_0489_1998.html | F27: falta | G27: alta | H27: Estructura del Estado, descentralización y delegación; autoridad competente.
A28: FALTAN · NORMAS COMPLEMENTARIAS (13)
A29: decreto_1083_2015 | B29: Decreto Único Reglamentario del Sector Función Pública (Decreto 1083 de 2015) | C29: decreto | D29: SUIN-Juriscol | E29: https://www.suin-juriscol.gov.co/legislacion/?q=Decreto%201083%20de%202015 | F29: falta | G29: media | H29: Reglamento de empleo público.
A30: ley_136_1994 | B30: Organización y funcionamiento de los municipios (Ley 136 de 1994) | C30: ley | D30: Secretaría del Senado | E30: http://www.secretariasenado.gov.co/senado/basedoc/ley_0136_1994.html | F30: falta | G30: media | H30: Competencias municipales (muestra 218: arts. 311 y 313 CP).
A31: ley_1474_2011 | B31: Estatuto Anticorrupción (Ley 1474 de 2011) | C31: ley | D31: Secretaría del Senado | E31: http://www.secretariasenado.gov.co/senado/basedoc/ley_1474_2011.html | F31: falta | G31: media | H31: Contratación, control y sanciones; también penal.
A32: ley_1882_2018 | B32: Reforma a la contratación estatal (Ley 1882 de 2018) | C32: ley | D32: Secretaría del Senado | E32: http://www.secretariasenado.gov.co/senado/basedoc/ley_1882_2018.html | F32: falta | G32: media | H32: Complementa Ley 80 y Ley 1150 (en el seed).
A33: ley_2080_2021 | B33: Reforma del CPACA (Ley 2080 de 2021) | C33: ley | D33: Secretaría del Senado | E33: http://www.secretariasenado.gov.co/senado/basedoc/ley_2080_2021.html | F33: falta | G33: media | H33: Vigencia temporal de las reformas al CPACA.
A34: ley_2094_2021 | B34: Reforma del Código General Disciplinario (Ley 2094 de 2021) | C34: ley | D34: Secretaría del Senado | E34: http://www.secretariasenado.gov.co/senado/basedoc/ley_2094_2021.html | F34: falta | G34: media | H34: Complementa el Código Disciplinario del seed.
A35: ley_610_2000 | B35: Proceso de responsabilidad fiscal (Ley 610 de 2000) | C35: ley | D35: Secretaría del Senado | E35: http://www.secretariasenado.gov.co/senado/basedoc/ley_0610_2000.html | F35: falta | G35: media | H35: Control fiscal; autoridad competente.
A36: ley_909_2004 | B36: Empleo público y carrera administrativa (Ley 909 de 2004) | C36: ley | D36: Secretaría del Senado | E36: http://www.secretariasenado.gov.co/senado/basedoc/ley_0909_2004.html | F36: falta | G36: media | H36: Función pública; requisitos y clasificación de empleos.
A37: resolucion_368_2014 | B37: Resolución 368 de 2014 del Ministerio de Ambiente y Desarrollo Sostenible | C37: resolución | D37: SUIN-Juriscol | E37: https://www.suin-juriscol.gov.co/legislacion/?q=Resoluci%C3%B3n%20368%20de%202014 | F37: falta · por verificar | G37: media | H37: La pregunta de muestra 748 pide leerla antes de responder; confirmar fuente y texto.
A38: decreto_19_2012 | B38: Decreto Ley Antitrámites (Decreto 19 de 2012) | C38: decreto | D38: SUIN-Juriscol | E38: https://www.suin-juriscol.gov.co/legislacion/?q=Decreto%2019%20de%202012 | F38: falta | G38: baja | H38: Simplificación de trámites.
A39: ley_1551_2012 | B39: Modernización de los municipios (Ley 1551 de 2012) | C39: ley | D39: Secretaría del Senado | E39: http://www.secretariasenado.gov.co/senado/basedoc/ley_1551_2012.html | F39: falta | G39: baja | H39: Modifica la Ley 136 de 1994.
A40: ley_2195_2022 | B40: Transparencia, prevención y lucha contra la corrupción (Ley 2195 de 2022) | C40: ley | D40: Secretaría del Senado | E40: http://www.secretariasenado.gov.co/senado/basedoc/ley_2195_2022.html | F40: falta | G40: baja | H40: Complementa el Estatuto Anticorrupción.
A41: ley_42_1993 | B41: Control fiscal (Ley 42 de 1993) | C41: ley | D41: Secretaría del Senado | E41: http://www.secretariasenado.gov.co/senado/basedoc/ley_0042_1993.html | F41: falta | G41: baja | H41: Organización del control fiscal.
A42: FALTAN · JURISPRUDENCIA (6)
A43: sentencia_su-277_2025 | B43: Sentencia SU-277 de 2025 · citada en la muestra | C43: sentencia | D43: Relatoría Corte Constitucional | E43: https://www.corteconstitucional.gov.co/relatoria/?q=Sentencia%20SU-277%20de%202025 | F43: falta | G43: alta | H43: Citada en legal_basis de muestra (id 563, como SU-277/25).
A44: ce_unificacion_seccion3_por_verificar | B44: Sentencias de unificación del Consejo de Estado, Sección Tercera (responsabilidad del Estado) | C44: sentencia | D44: Relatoría Consejo de Estado | E44: https://www.consejodeestado.gov.co | F44: falta · por verificar | G44: media | H44: Reparación directa y títulos de imputación; identificar radicados con los compañeros de derecho.
A45: sentencia_c-634_2011 | B45: Sentencia C-634 de 2011 · deber de las autoridades administrativas de seguir el precedente | C45: sentencia | D45: Relatoría Corte Constitucional | E45: https://www.corteconstitucional.gov.co/relatoria/?q=Sentencia%20C-634%20de%202011 | F45: falta | G45: media | H45: Art. 10 CPACA; precedente jurisprudencial.
A46: sentencia_c-816_2011 | B46: Sentencia C-816 de 2011 · extensión de la jurisprudencia del Consejo de Estado | C46: sentencia | D46: Relatoría Corte Constitucional | E46: https://www.corteconstitucional.gov.co/relatoria/?q=Sentencia%20C-816%20de%202011 | F46: falta · por verificar | G46: media | H46: Art. 102 CPACA.
...

Sheet Penal
A1: Penal · 123 preguntas en el banco
A2: Estados: 'en seed' = viene en seed_targets.json · 'falta' = hay que agregarlo · 'por verificar' = confirmar número, año o URL antes de descargar.
A4: doc_id | B4: título | C4: tipo | D4: fuente | E4: URL | F4: estado | G4: prioridad | H4: justificación
A5: EN EL SEED (18 documentos)
A6: constitucion_1991 | B6: Constitución Política de 1991 | C6: constitución | D6: Secretaría del Senado | E6: http://www.secretariasenado.gov.co/senado/basedoc/constitucion_politica_1991.html?q=Constitucion | F6: en seed | G6: alta | H6: Norma más citada del banco. Jerarquía, existencia normativa, ponderación y conflicto normativo en todas las áreas. Citada en 90 ítem(s) del banco según el seed. En legal_basis de muestra (ids 51, 60, 218, 661, 1005, 1073).
A7: ley_1564_2012 | B7: Código General del Proceso (Ley 1564 de 2012) | C7: código | D7: Secretaría del Senado | E7: http://www.secretariasenado.gov.co/senado/basedoc/?q=Codigo%20general%20proceso | F7: en seed | G7: alta | H7: Juez que decide, autoridad competente, requisitos y términos; transversal a civil, familia y comercial. Citada en 65 ítem(s) del banco según el seed. En legal_basis de muestra (ids 58, 60, 528, 589, 879).
A8: sentencia_c-355_2006 | B8: Sentencia C-355 de 2006 · Corte Constitucional · despenalización parcial del aborto | C8: sentencia | D8: Relatoría Corte Constitucional | E8: https://www.corteconstitucional.gov.co/relatoria/?q=Sentencia%20C-355%20de%202006 | F8: en seed | G8: alta | H8: Citada en 7 ítem(s) del banco según el seed. En legal_basis de muestra (ids 1015).
A9: sentencia_c-055_2022 | B9: Sentencia C-55 de 2022 · Corte Constitucional | C9: sentencia | D9: Relatoría Corte Constitucional | E9: https://www.corteconstitucional.gov.co/relatoria/?q=Sentencia%20C-55%20de%202022 | F9: en seed | G9: media | H9: Citada en 3 ítem(s) del banco según el seed.
A10: ley_1095_2006 | B10: Ley 1095 de 2006 (hábeas corpus) | C10: ley | D10: SUIN-Juriscol | E10: https://www.suin-juriscol.gov.co/legislacion/?q=Ley%201095%20de%202006 | F10: en seed | G10: media | H10: Citada en 2 ítem(s) del banco según el seed.
A11: sentencia_c-015_2018 | B11: Sentencia C-15 de 2018 · Corte Constitucional | C11: sentencia | D11: Relatoría Corte Constitucional | E11: https://www.corteconstitucional.gov.co/relatoria/?q=Sentencia%20C-15%20de%202018 | F11: en seed | G11: media | H11: Citada en 2 ítem(s) del banco según el seed.
A12: sentencia_c-164_2022 | B12: Sentencia C-164 de 2022 · Corte Constitucional | C12: sentencia | D12: Relatoría Corte Constitucional | E12: https://www.corteconstitucional.gov.co/relatoria/?q=Sentencia%20C-164%20de%202022 | F12: en seed | G12: media | H12: Citada en 2 ítem(s) del banco según el seed.
A13: sentencia_c-431_2001 | B13: Sentencia C-431 de 2001 · Corte Constitucional | C13: sentencia | D13: Relatoría Corte Constitucional | E13: https://www.corteconstitucional.gov.co/relatoria/?q=Sentencia%20C-431%20de%202001 | F13: en seed | G13: media | H13: Citada en 2 ítem(s) del banco según el seed.
A14: sentencia_sp-1680_2022 | B14: Sentencia SP-1680 de 2022 · Corte Suprema, Sala Penal | C14: sentencia | D14: Relatoría Corte Suprema de Justicia | E14: https://www.corteconstitucional.gov.co/relatoria/?q=Sentencia%20SP-1680%20de%202022 | F14: en seed | G14: media | H14: Citada en 2 ítem(s) del banco según el seed. El seed apunta a la relatoría de la Corte Constitucional; buscarla en la de la Corte Suprema.
A15: sentencia_sp-1945_2019 | B15: Sentencia SP-1945 de 2019 · Corte Suprema, Sala Penal | C15: sentencia | D15: Relatoría Corte Suprema de Justicia | E15: https://www.corteconstitucional.gov.co/relatoria/?q=Sentencia%20SP-1945%20de%202019 | F15: en seed | G15: media | H15: Citada en 2 ítem(s) del banco según el seed. El seed apunta a la relatoría de la Corte Constitucional; buscarla en la de la Corte Suprema.
A16: sentencia_su-429_2024 | B16: Sentencia SU-429 de 2024 · Corte Constitucional | C16: sentencia | D16: Relatoría Corte Constitucional | E16: https://www.corteconstitucional.gov.co/relatoria/?q=Sentencia%20SU-429%20de%202024 | F16: en seed | G16: media | H16: Citada en 1 ítem(s) del banco según el seed.
A17: decreto_780_2016 | B17: Decreto 780 de 2016 (Decreto Único del sector Salud) | C17: decreto | D17: SUIN-Juriscol | E17: https://www.suin-juriscol.gov.co/legislacion/?q=Decreto%20780%20de%202016 | F17: en seed | G17: baja | H17: Citada en 1 ítem(s) del banco según el seed.
... A23: sentencia_t-248_2025 | B23: Sentencia T-248 de 2025 · Corte Constitucional | C23: sentencia | D23: Relatoría Corte Constitucional | E23: https://www.corteconstitucional.gov.co/relatoria/?q=Sentencia%20T-248%20de%202025 | F23: en seed | G23: baja | H23: Citada en 1 ítem(s) del banco según el seed.
A24: FALTAN · NORMAS BASE (2)
A25: ley_599_2000 | B25: Código Penal (Ley 599 de 2000) | C25: código | D25: Secretaría del Senado | E25: http://www.secretariasenado.gov.co/senado/basedoc/ley_0599_2000.html | F25: falta | G25: alta | H25: Citado en legal_basis de muestra (ids 280, 600, 1065). Tipos penales, dosificación, subrogados.
A26: ley_906_2004 | B26: Código de Procedimiento Penal (Ley 906 de 2004) | C26: ley | D26: Secretaría del Senado | E26: http://www.secretariasenado.gov.co/senado/basedoc/ley_0906_2004.html | F26: falta | G26: alta | H26: Procedimiento acusatorio; juez que decide, postura procesal y requisitos.
A27: FALTAN · NORMAS COMPLEMENTARIAS (10)
A28: ley_1257_2008 | B28: Violencia y discriminación contra la mujer (Ley 1257 de 2008) | C28: ley | D28: Secretaría del Senado | E28: http://www.secretariasenado.gov.co/senado/basedoc/ley_1257_2008.html | F28: falta | G28: media | H28: Violencia contra la mujer; también familia.
A29: ley_1453_2011 | B29: Seguridad ciudadana (Ley 1453 de 2011) | C29: ley | D29: Secretaría del Senado | E29: http://www.secretariasenado.gov.co/senado/basedoc/ley_1453_2011.html | F29: falta | G29: media | H29: Reforma Código Penal y CPP.
A30: ley_1709_2014 | B30: Reforma al Código Penitenciario (Ley 1709 de 2014) | C30: ley | D30: Secretaría del Senado | E30: http://www.secretariasenado.gov.co/senado/basedoc/ley_1709_2014.html | F30: falta | G30: media | H30: Subrogados penales y vigencia temporal.
A31: ley_1761_2015 | B31: Tipo penal de feminicidio (Ley 1761 de 2015) | C31: ley | D31: Secretaría del Senado | E31: http://www.secretariasenado.gov.co/senado/basedoc/ley_1761_2015.html | F31: falta | G31: media | H31: Existencia normativa de tipos penales.
A32: ley_1826_2017 | B32: Procedimiento penal abreviado y acusador privado (Ley 1826 de 2017) | C32: ley | D32: Secretaría del Senado | E32: http://www.secretariasenado.gov.co/senado/basedoc/ley_1826_2017.html | F32: falta | G32: media | H32: Postura procesal y procedimiento especial.
A33: ley_65_1993 | B33: Código Penitenciario y Carcelario (Ley 65 de 1993) | C33: ley | D33: Secretaría del Senado | E33: http://www.secretariasenado.gov.co/senado/basedoc/ley_0065_1993.html | F33: falta | G33: media | H33: Ejecución de la pena; libertad condicional (muestra 280 junto al Código Penal).
A34: ley_1121_2006 | B34: Financiación del terrorismo (Ley 1121 de 2006) | C34: ley | D34: Secretaría del Senado | E34: http://www.secretariasenado.gov.co/senado/basedoc/ley_1121_2006.html | F34: falta | G34: baja | H34: Exclusión de beneficios; tipos especiales.
A35: ley_1273_2009 | B35: Delitos informáticos (Ley 1273 de 2009) | C35: ley | D35: Secretaría del Senado | E35: http://www.secretariasenado.gov.co/senado/basedoc/ley_1273_2009.html | F35: falta | G35: baja | H35: Tipos penales especiales.
A36: ley_2098_2021 | B36: Prisión perpetua revisable (Ley 2098 de 2021) | C36: ley | D36: Secretaría del Senado | E36: http://www.secretariasenado.gov.co/senado/basedoc/ley_2098_2021.html | F36: falta | G36: baja | H36: Declarada inexequible (C-294 de 2021): vigencia temporal.
A37: ley_2197_2022 | B37: Seguridad ciudadana (Ley 2197 de 2022) | C37: ley | D37: Secretaría del Senado | E37: http://www.secretariasenado.gov.co/senado/basedoc/ley_2197_2022.html | F37: falta | G37: baja | H37: Reformas recientes al Código Penal.
A38: FALTAN · JURISPRUDENCIA (4)
A39: csj_penal_hitos_por_verificar | B39: Sentencias hito de la Sala de Casación Penal (Corte Suprema) | C39: sentencia | D39: Relatoría Corte Suprema de Justicia | E39: https://cortesuprema.gov.co | F39: falta · por verificar | G39: media | H39: El seed trae 4 SP; completar con hitos que indiquen los compañeros de derecho.
A40: sentencia_c-221_1994 | B40: Sentencia C-221 de 1994 · dosis personal y libre desarrollo de la personalidad | C40: sentencia | D40: Relatoría Corte Constitucional | E40: https://www.corteconstitucional.gov.co/relatoria/?q=Sentencia%20C-221%20de%201994 | F40: falta | G40: media | H40: Ponderación de principios; también constitucional.
A41: sentencia_c-294_2021 | B41: Sentencia C-294 de 2021 · inexequibilidad de la prisión perpetua revisable | C41: sentencia | D41: Relatoría Corte Constitucional | E41: https://www.corteconstitucional.gov.co/relatoria/?q=Sentencia%20C-294%20de%202021 | F41: falta | G41: media | H41: Vigencia y control de reformas constitucionales en materia penal.
A42: sentencia_c-591_2005 | B42: Sentencia C-591 de 2005 · sistema penal acusatorio y cláusula de exclusión | C42: sentencia | D42: Relatoría Corte Constitucional | E42: https://www.corteconstitucional.gov.co/relatoria/?q=Sentencia%20C-591%20de%202005 | F42: falta · por verificar | G42: media | H42: Postura procesal en el CPP.
A44: legal_basis de muestra que el seed no cubre
A45: id pregunta | B45: legal_basis (texto original) | C45: norma no cubierta | D45: se cubre con (doc_id)
A46: 600 | B46: Artículo 241 del Código Penal. | C46: Código Penal | D46: ley_599_2000
A47: 280 | B47: Artículo 64 del código penal colombiano | C47: Código Penal | D47: ley_599_2000
...

Sheet Procesal
A1: Procesal · 111 preguntas en el banco
A2: Estados: 'en seed' = viene en seed_targets.json · 'falta' = hay que agregarlo · 'por verificar' = confirmar número, año o URL antes de descargar.
A4: doc_id | B4: título | C4: tipo | D4: fuente | E4: URL | F4: estado | G4: prioridad | H4: justificación
A5: EN EL SEED (10 documentos)
A6: constitucion_1991 | B6: Constitución Política de 1991 | C6: constitución | D6: Secretaría del Senado | E6: http://www.secretariasenado.gov.co/senado/basedoc/constitucion_politica_1991.html?q=Constitucion | F6: en seed | G6: alta | H6: Norma más citada del banco. Jerarquía, existencia normativa, ponderación y conflicto normativo en todas las áreas. Citada en 90 ítem(s) del banco según el seed. En legal_basis de muestra (ids 51, 60, 218, 661, 1005, 1073).
A7: ley_1564_2012 | B7: Código General del Proceso (Ley 1564 de 2012) | C7: código | D7: Secretaría del Senado | E7: http://www.secretariasenado.gov.co/senado/basedoc/?q=Codigo%20general%20proceso | F7: en seed | G7: alta | H7: Juez que decide, autoridad competente, requisitos y términos; transversal a civil, familia y comercial. Citada en 65 ítem(s) del banco según el seed. En legal_basis de muestra (ids 58, 60, 528, 589, 879).
A8: ley_2220_2022 | B8: Ley 2220 de 2022 (Estatuto de Conciliación) | C8: ley | D8: SUIN-Juriscol | E8: https://www.suin-juriscol.gov.co/legislacion/?q=Ley%202220%20de%202022 | F8: en seed | G8: alta | H8: Citada en 11 ítem(s) del banco según el seed.
A9: ley_1116_2006 | B9: Ley 1116 de 2006 (régimen de insolvencia empresarial) | C9: ley | D9: SUIN-Juriscol | E9: https://www.suin-juriscol.gov.co/legislacion/?q=Ley%201116%20de%202006 | F9: en seed | G9: alta | H9: Citada en 7 ítem(s) del banco según el seed. En legal_basis de muestra (ids 272).
A10: ley_2437_2024 | B10: Ley 2437 de 2024 | C10: ley | D10: SUIN-Juriscol | E10: https://www.suin-juriscol.gov.co/legislacion/?q=Ley%202437%20de%202024 | F10: en seed | G10: media | H10: Citada en 3 ítem(s) del banco según el seed.
A11: sentencia_c-259_2015 | B11: Sentencia C-259 de 2015 · Corte Constitucional | C11: sentencia | D11: Relatoría Corte Constitucional | E11: https://www.corteconstitucional.gov.co/relatoria/?q=Sentencia%20C-259%20de%202015 | F11: en seed | G11: media | H11: Citada en 2 ítem(s) del banco según el seed.
A12: sentencia_c-500_2024 | B12: Sentencia C-500 de 2024 · Corte Constitucional | C12: sentencia | D12: Relatoría Corte Constitucional | E12: https://www.corteconstitucional.gov.co/relatoria/?q=Sentencia%20C-500%20de%202024 | F12: en seed | G12: media | H12: Citada en 2 ítem(s) del banco según el seed.
A13: decreto_1563_2012 | B13: Decreto 1563 de 2012 | C13: decreto | D13: SUIN-Juriscol | E13: https://www.suin-juriscol.gov.co/legislacion/?q=Decreto%201563%20de%202012 | F13: en seed · revisar | G13: baja | H13: Citada en 2 ítem(s) del banco según el seed. El Estatuto de Arbitraje es la Ley 1563 de 2012: buscar como ley (ver Procesal).
A14: ley_1801_2016 | B14: Código Nacional de Seguridad y Convivencia Ciudadana (Ley 1801 de 2016) | C14: código | D14: Secretaría del Senado | E14: http://www.secretariasenado.gov.co/senado/basedoc/?q=Codigo%20nacional%20policia | F14: en seed | G14: baja | H14: Citada en 1 ítem(s) del banco según el seed.
A15: ley_678_2001 | B15: Ley 678 de 2001 (acción de repetición) | C15: ley | D15: SUIN-Juriscol | E15: https://www.suin-juriscol.gov.co/legislacion/?q=Ley%20678%20de%202001 | F15: en seed | G15: baja | H15: Citada en 1 ítem(s) del banco según el seed.
A16: FALTAN · NORMAS BASE (4)
A17: ley_1437_2011 | B17: Código de Procedimiento Administrativo y de lo Contencioso Administrativo (CPACA, Ley 1437 de 2011) | C17: ley | D17: Secretaría del Senado | E17: http://www.secretariasenado.gov.co/senado/basedoc/ley_1437_2011.html | F17: falta | G17: alta | H17: Citado en legal_basis de muestra (id 1089, art. 246). Procedimiento contencioso administrativo.
A18: ley_1563_2012 | B18: Estatuto de Arbitraje Nacional e Internacional (Ley 1563 de 2012) | C18: ley | D18: Secretaría del Senado | E18: http://www.secretariasenado.gov.co/senado/basedoc/ley_1563_2012.html | F18: falta | G18: alta | H18: El seed la lista como 'Decreto 1563 de 2012' (2 ítems); buscarla como ley.
A19: ley_270_1996 | B19: Ley Estatutaria de la Administración de Justicia (Ley 270 de 1996) | C19: ley | D19: Secretaría del Senado | E19: http://www.secretariasenado.gov.co/senado/basedoc/ley_0270_1996.html | F19: falta | G19: alta | H19: Competencias, jerarquía y funcionamiento de la Rama Judicial.
A20: ley_906_2004 | B20: Código de Procedimiento Penal (Ley 906 de 2004) | C20: ley | D20: Secretaría del Senado | E20: http://www.secretariasenado.gov.co/senado/basedoc/ley_0906_2004.html | F20: falta | G20: alta | H20: Procedimiento penal; juez que decide y términos.
A21: FALTAN · NORMAS COMPLEMENTARIAS (4)
A22: decreto_2158_1948 | B22: Código Procesal del Trabajo anterior (Decreto Ley 2158 de 1948) | C22: código | D22: Secretaría del Senado | E22: http://www.secretariasenado.gov.co/senado/basedoc/codigo_procedimental_laboral.html | F22: falta | G22: media | H22: Procesos laborales iniciados antes del 6 de abril de 2026; el nuevo CPTSS (Ley 2452 de 2025) ya está en el seed.
A23: ley_2213_2022 | B23: Uso de las TIC en actuaciones judiciales (Ley 2213 de 2022) | C23: ley | D23: Secretaría del Senado | E23: http://www.secretariasenado.gov.co/senado/basedoc/ley_2213_2022.html | F23: falta | G23: media | H23: Notificaciones y audiencias virtuales; vigencia temporal.
A24: decreto_806_2020 | B24: Medidas de virtualidad en la justicia durante la emergencia (Decreto 806 de 2020) | C24: decreto | D24: SUIN-Juriscol | E24: https://www.suin-juriscol.gov.co/legislacion/?q=Decreto%20806%20de%202020 | F24: falta | G24: baja | H24: Antecedente de la Ley 2213 de 2022.
A25: ley_1285_2009 | B25: Reforma a la Ley Estatutaria de la Administración de Justicia (Ley 1285 de 2009) | C25: ley | D25: Secretaría del Senado | E25: http://www.secretariasenado.gov.co/senado/basedoc/ley_1285_2009.html | F25: falta | G25: baja | H25: Complementa la Ley 270 de 1996.
A26: FALTAN · JURISPRUDENCIA (3)
A27: sentencia_c-420_2020 | B27: Sentencia C-420 de 2020 · control del Decreto 806 de 2020 | C27: sentencia | D27: Relatoría Corte Constitucional | E27: https://www.corteconstitucional.gov.co/relatoria/?q=Sentencia%20C-420%20de%202020 | F27: falta | G27: media | H27: Notificaciones y virtualidad.
A28: sentencia_c-543_1992 | B28: Sentencia C-543 de 1992 · tutela contra providencias judiciales (primer pronunciamiento) | C28: sentencia | D28: Relatoría Corte Constitucional | E28: https://www.corteconstitucional.gov.co/relatoria/?q=Sentencia%20C-543%20de%201992 | F28: falta | G28: media | H28: Evolución de la tutela contra sentencias.
A29: sentencia_c-590_2005 | B29: Sentencia C-590 de 2005 · causales de procedencia de la tutela contra providencias judiciales | C29: sentencia | D29: Relatoría Corte Constitucional | E29: https://www.corteconstitucional.gov.co/relatoria/?q=Sentencia%20C-590%20de%202005 | F29: falta | G29: media | H29: Hito: requisitos generales y especiales de la tutela contra sentencias; sub-tareas juez que decide y precedente.
A31: legal_basis de muestra que el seed no cubre
A32: id pregunta | B32: legal_basis (texto original) | C32: norma no cubierta | D32: se cubre con (doc_id)
A33: 1089 | B33: Artículo 246 del CPACA. | C33: CPACA | D33: ley_1437_2011

Sheet Comercial
A1: Comercial · 104 preguntas en el banco
A2: Estados: 'en seed' = viene en seed_targets.json · 'falta' = hay que agregarlo · 'por verificar' = confirmar número, año o URL antes de descargar.
A4: doc_id | B4: título | C4: tipo | D4: fuente | E4: URL | F4: estado | G4: prioridad | H4: justificación
A5: EN EL SEED (20 documentos)
A6: constitucion_1991 | B6: Constitución Política de 1991 | C6: constitución | D6: Secretaría del Senado | E6: http://www.secretariasenado.gov.co/senado/basedoc/constitucion_politica_1991.html?q=Constitucion | F6: en seed | G6: alta | H6: Norma más citada del banco. Jerarquía, existencia normativa, ponderación y conflicto normativo en todas las áreas. Citada en 90 ítem(s) del banco según el seed. En legal_basis de muestra (ids 51, 60, 218, 661, 1005, 1073).
A7: ley_1564_2012 | B7: Código General del Proceso (Ley 1564 de 2012) | C7: código | D7: Secretaría del Senado | E7: http://www.secretariasenado.gov.co/senado/basedoc/?q=Codigo%20general%20proceso | F7: en seed | G7: alta | H7: Juez que decide, autoridad competente, requisitos y términos; transversal a civil, familia y comercial. Citada en 65 ítem(s) del banco según el seed. En legal_basis de muestra (ids 58, 60, 528, 589, 879).
A8: decision_486_2000 | B8: Decisión Andina 486 de 2000 (régimen común de propiedad industrial) | C8: decisión andina | D8: Secretaría del Senado | E8: http://www.secretariasenado.gov.co/senado/basedoc/?q=Decision%20andina%20486 | F8: en seed | G8: alta | H8: Propiedad industrial: marcas, patentes, diseños. Citada en 23 ítem(s) del banco según el seed.
A9: ley_1116_2006 | B9: Ley 1116 de 2006 (régimen de insolvencia empresarial) | C9: ley | D9: SUIN-Juriscol | E9: https://www.suin-juriscol.gov.co/legislacion/?q=Ley%201116%20de%202006 | F9: en seed | G9: alta | H9: Citada en 7 ítem(s) del banco según el seed. En legal_basis de muestra (ids 272).
A10: ley_1258_2008 | B10: Ley 1258 de 2008 (sociedad por acciones simplificada) | C10: ley | D10: SUIN-Juriscol | E10: https://www.suin-juriscol.gov.co/legislacion/?q=Ley%201258%20de%202008 | F10: en seed | G10: alta | H10: Citada en 4 ítem(s) del banco según el seed.
A11: decreto_663_1993 | B11: Decreto 663 de 1993 (Estatuto Orgánico del Sistema Financiero) | C11: decreto | D11: SUIN-Juriscol | E11: https://www.suin-juriscol.gov.co/legislacion/?q=Decreto%20663%20de%201993 | F11: en seed | G11: alta | H11: Citada en 1 ítem(s) del banco según el seed. En legal_basis de muestra (ids 128).
A12: sentencia_c-145_2018 | B12: Sentencia C-145 de 2018 · Corte Constitucional · potestades del acreedor garantizado en insolvencia | C12: sentencia | D12: Relatoría Corte Constitucional | E12: https://www.corteconstitucional.gov.co/relatoria/?q=Sentencia%20C-145%20de%202018 | F12: en seed | G12: alta | H12: Citada en 1 ítem(s) del banco según el seed. En legal_basis de muestra (ids 140).
A13: decreto_24_2016 | B13: Decreto 24 de 2016 | C13: decreto | D13: SUIN-Juriscol | E13: https://www.suin-juriscol.gov.co/legislacion/?q=Decreto%2024%20de%202016 | F13: en seed | G13: baja | H13: Citada en 1 ítem(s) del banco según el seed.
A14: decreto_4334_2008 | B14: Decreto 4334 de 2008 | C14: decreto | D14: SUIN-Juriscol | E14: https://www.suin-juriscol.gov.co/legislacion/?q=Decreto%204334%20de%202008 | F14: en seed | G14: baja | H14: Citada en 1 ítem(s) del banco según el seed.
A15: decreto_46_2024 | B15: Decreto 046 de 2024 | C15: decreto | D15: SUIN-Juriscol | E15: https://www.suin-juriscol.gov.co/legislacion/?q=Decreto%20046%20de%202024 | F15: en seed | G15: baja | H15: Citada en 1 ítem(s) del banco según el seed.
A16: ley_1700_2013 | B16: Ley 1700 de 2013 (actividades de comercialización en red) | C16: ley | D16: SUIN-Juriscol | E16: https://www.suin-juriscol.gov.co/legislacion/?q=Ley%201700%20de%202013 | F16: en seed | G16: baja | H16: Citada en 1 ítem(s) del banco según el seed.
A17: ley_527_1999 | B17: Ley 527 de 1999 (comercio electrónico) | C17: ley | D17: SUIN-Juriscol | E17: https://www.suin-juriscol.gov.co/legislacion/?q=Ley%20527%20de%201999 | F17: en seed | G17: baja | H17: Citada en 1 ítem(s) del banco según el seed.
... A25: sentencia_sc-8453_2016 | B25: Sentencia SC-8453 de 2016 · Corte Suprema, Sala Civil | C25: sentencia | D25: Relatoría Corte Suprema de Justicia | E25: https://www.corteconstitucional.gov.co/relatoria/?q=Sentencia%20SC-8453%20de%202016 | F25: en seed | G25: baja | H25: Citada en 1 ítem(s) del banco según el seed. El seed apunta a la relatoría de la Corte Constitucional; buscarla en la de la Corte Suprema.
A26: FALTAN · NORMAS BASE (2)
A27: decreto_410_1971 | B27: Código de Comercio (Decreto 410 de 1971) | C27: código | D27: Secretaría del Senado | E27: http://www.secretariasenado.gov.co/senado/basedoc/codigo_comercio.html | F27: falta | G27: alta | H27: Citado en legal_basis de muestra (id 239: arts. 1324, 1325, 822 y 871). Contratos mercantiles, sociedades, títulos valores.
A28: ley_222_1995 | B28: Régimen de sociedades (Ley 222 de 1995) | C28: ley | D28: Secretaría del Senado | E28: http://www.secretariasenado.gov.co/senado/basedoc/ley_0222_1995.html | F28: falta | G28: alta | H28: Reforma al Libro II del Código de Comercio; sociedades y responsabilidad de administradores.
A29: FALTAN · NORMAS COMPLEMENTARIAS (7)
A30: decreto_1074_2015 | B30: Decreto Único Reglamentario del Sector Comercio, Industria y Turismo (Decreto 1074 de 2015) | C30: decreto | D30: SUIN-Juriscol | E30: https://www.suin-juriscol.gov.co/legislacion/?q=Decreto%201074%20de%202015 | F30: falta | G30: media | H30: Reglamentos de sociedades, registro mercantil y consumidor.
A31: ley_1328_2009 | B31: Protección al consumidor financiero (Ley 1328 de 2009) | C31: ley | D31: Secretaría del Senado | E31: http://www.secretariasenado.gov.co/senado/basedoc/ley_1328_2009.html | F31: falta | G31: media | H31: Relaciones con entidades financieras; también mercados.
A32: ley_1676_2013 | B32: Garantías mobiliarias (Ley 1676 de 2013) | C32: ley | D32: Secretaría del Senado | E32: http://www.secretariasenado.gov.co/senado/basedoc/ley_1676_2013.html | F32: falta | G32: media | H32: Garantías mobiliarias; contexto de la C-145 de 2018 (en el seed, muestra 140).
A33: decreto_2555_2010 | B33: Decreto Único del mercado de valores (Decreto 2555 de 2010) | C33: decreto | D33: SUIN-Juriscol | E33: https://www.suin-juriscol.gov.co/legislacion/?q=Decreto%202555%20de%202010 | F33: falta | G33: baja | H33: Mercado de valores; complementa la Ley 964 del seed.
A34: ley_1231_2008 | B34: Factura electrónica como título valor (Ley 1231 de 2008) | C34: ley | D34: Secretaría del Senado | E34: http://www.secretariasenado.gov.co/senado/basedoc/ley_1231_2008.html | F34: falta | G34: baja | H34: Títulos valores.
A35: ley_1429_2010 | B35: Formalización y generación de empleo (Ley 1429 de 2010) | C35: ley | D35: Secretaría del Senado | E35: http://www.secretariasenado.gov.co/senado/basedoc/ley_1429_2010.html | F35: falta | G35: baja | H35: Aspectos societarios y de registro.
A36: ley_2069_2020 | B36: Emprendimiento (Ley 2069 de 2020) | C36: ley | D36: Secretaría del Senado | E36: http://www.secretariasenado.gov.co/senado/basedoc/ley_2069_2020.html | F36: falta | G36: baja | H36: Sociedades BIC y régimen empresarial reciente.
A37: FALTAN · JURISPRUDENCIA (2)
A38: sentencia_csj_civil_cesantia_comercial_por_verificar | B38: Sentencia de la Sala Civil de la Corte Suprema sobre renuncia a la cesantía comercial del agente (muestra 239) | C38: sentencia | D38: Relatoría Corte Suprema de Justicia | E38: https://cortesuprema.gov.co | F38: falta · por verificar | G38: alta | H38: Muestra id 239 (la pregunta la describe pero no da número); identificar radicado.
A39: auto_supersociedades_2025-01-730337 | B39: Auto 2025-01-730337 de la Superintendencia de Sociedades (muestra 272) | C39: auto | D39: Superintendencia de Sociedades (fuera de la lista de fuentes) | E39: https://www.supersociedades.gov.co | F39: falta · por verificar | G39: media | H39: Muestra id 272. La Superintendencia no está en la lista de fuentes permitidas: consultar a los organizadores antes de incluirla.
A41: legal_basis de muestra que el seed no cubre
A42: id pregunta | B42: legal_basis (texto original) | C42: norma no cubierta | D42: se cubre con (doc_id)
A43: 272 | B43: Ley 1116 de 2006 y jurisprudencia de la superintendencia de sociedades en especial el auto auto No. 2025-01-730337 | C43: Auto 2025-01-730337 de la Superintendencia de Sociedades · Fuente fuera de la lista permitida: consultar a los organizadores. | D43: auto_supersociedades_2025-01-730337
A44: 239 | B44: Artículos 1324 y 1325 del Código de Comercio. Así como en los principios de autonomía de la voluntad privada (Artículos 16, 822 y 871). | C44: Código de Comercio | D44: decreto_410_1971
A45: 239 | B45: Artículos 1324 y 1325 del Código de Comercio. Así como en los principios de autonomía de la voluntad privada (Artículos 16, 822 y 871). | C45: Sentencia CSJ sobre cesantía comercial · La pregunta la describe sin número: por verificar. | D45: sentencia_csj_civil_cesantia_comercial_por_verificar
A46: 697 | B46: caso francés de Dow Chemical | C46: 'Caso francés de Dow Chemical' · Doctrina arbitral extranjera: no cubrible con fuentes admitidas. | D46: —

Sheet Civil
A1: Civil · 102 preguntas en el banco
A2: Estados: 'en seed' = viene en seed_targets.json · 'falta' = hay que agregarlo · 'por verificar' = confirmar número, año o URL antes de descargar.
A4: doc_id | B4: título | C4: tipo | D4: fuente | E4: URL | F4: estado | G4: prioridad | H4: justificación
A5: EN EL SEED (24 documentos)
A6: ley_1564_2012 | B6: Código General del Proceso (Ley 1564 de 2012) | C6: código | D6: Secretaría del Senado | E6: http://www.secretariasenado.gov.co/senado/basedoc/?q=Codigo%20general%20proceso | F6: en seed | G6: alta | H6: Juez que decide, autoridad competente, requisitos y términos; transversal a civil, familia y comercial. Citada en 65 ítem(s) del banco según el seed. En legal_basis de muestra (ids 58, 60, 528, 589, 879).
A7: decreto_624_1989 | B7: Estatuto Tributario (Decreto 624 de 1989) | C7: código | D7: Secretaría del Senado | E7: http://www.secretariasenado.gov.co/senado/basedoc/?q=Estatuto%20tributario | F7: en seed | G7: alta | H7: Definiciones, requisitos y vigencia temporal en tributario. Citada en 35 ítem(s) del banco según el seed.
A8: ley_1480_2011 | B8: Estatuto del Consumidor (Ley 1480 de 2011) | C8: código | D8: Secretaría del Senado | E8: http://www.secretariasenado.gov.co/senado/basedoc/?q=Estatuto%20consumidor | F8: en seed | G8: alta | H8: Consumidor y funciones jurisdiccionales de la SIC. Citada en 13 ítem(s) del banco según el seed. En legal_basis de muestra (ids 58, 674).
A9: ley_2220_2022 | B9: Ley 2220 de 2022 (Estatuto de Conciliación) | C9: ley | D9: SUIN-Juriscol | E9: https://www.suin-juriscol.gov.co/legislacion/?q=Ley%202220%20de%202022 | F9: en seed | G9: alta | H9: Citada en 11 ítem(s) del banco según el seed.
A10: ley_153_1887 | B10: Ley 153 de 1887 (reglas de interpretación y aplicación de las leyes) | C10: ley | D10: SUIN-Juriscol | E10: https://www.suin-juriscol.gov.co/legislacion/?q=Ley%20153%20de%201887 | F10: en seed | G10: alta | H10: Citada en 3 ítem(s) del banco según el seed.
A11: sentencia_su-455_2020 | B11: Sentencia SU-455 de 2020 · Corte Constitucional | C11: sentencia | D11: Relatoría Corte Constitucional | E11: https://www.corteconstitucional.gov.co/relatoria/?q=Sentencia%20SU-455%20de%202020 | F11: en seed | G11: alta | H11: Citada en 1 ítem(s) del banco según el seed. En legal_basis de muestra (ids 919).
A12: ley_2437_2024 | B12: Ley 2437 de 2024 | C12: ley | D12: SUIN-Juriscol | E12: https://www.suin-juriscol.gov.co/legislacion/?q=Ley%202437%20de%202024 | F12: en seed | G12: media | H12: Citada en 3 ítem(s) del banco según el seed.
A13: sentencia_su-315_2025 | B13: Sentencia SU-315 de 2025 · Corte Constitucional | C13: sentencia | D13: Relatoría Corte Constitucional | E13: https://www.corteconstitucional.gov.co/relatoria/?q=Sentencia%20SU-315%20de%202025 | F13: en seed | G13: media | H13: Citada en 3 ítem(s) del banco según el seed.
A14: sentencia_c-748_2011 | B14: Sentencia C-748 de 2011 · Corte Constitucional · control de la ley de datos personales | C14: sentencia | D14: Relatoría Corte Constitucional | E14: https://www.corteconstitucional.gov.co/relatoria/?q=Sentencia%20C-748%20de%202011 | F14: en seed | G14: media | H14: Citada en 2 ítem(s) del banco según el seed.
A15: sentencia_su-138_2024 | B15: Sentencia SU-138 de 2024 · Corte Constitucional | C15: sentencia | D15: Relatoría Corte Constitucional | E15: https://www.corteconstitucional.gov.co/relatoria/?q=Sentencia%20SU-138%20de%202024 | F15: en seed | G15: media | H15: Citada en 1 ítem(s) del banco según el seed.
A16: sentencia_su-207_2022 | B16: Sentencia SU-207 de 2022 · Corte Constitucional | C16: sentencia | D16: Relatoría Corte Constitucional | E16: https://www.corteconstitucional.gov.co/relatoria/?q=Sentencia%20SU-207%20de%202022 | F16: en seed | G16: media | H16: Citada en 1 ítem(s) del banco según el seed.
A17: sentencia_su-380_2021 | B17: Sentencia SU-380 de 2021 · Corte Constitucional | C17: sentencia | D17: Relatoría Corte Constitucional | E17: https://www.corteconstitucional.gov.co/relatoria/?q=Sentencia%20SU-380%20de%202021 | F17: en seed | G17: media | H17: Citada en 1 ítem(s) del banco según el seed.
... A29: sentencia_t-026_2025 | B29: Sentencia T-26 de 2025 · Corte Constitucional | C29: sentencia | D29: Relatoría Corte Constitucional | E29: https://www.corteconstitucional.gov.co/relatoria/?q=Sentencia%20T-26%20de%202025 | F29: en seed | G29: baja | H29: Citada en 1 ítem(s) del banco según el seed.
A30: FALTAN · NORMAS BASE (1)
A31: ley_84_1873 | B31: Código Civil (Ley 84 de 1873, adoptado por la Ley 57 de 1887) | C31: código | D31: Secretaría del Senado | E31: http://www.secretariasenado.gov.co/senado/basedoc/codigo_civil.html | F31: falta | G31: alta | H31: Citado en legal_basis de muestra (id 358, art. 946). Obligaciones, contratos, bienes, sucesiones; muestra 24 (elementos del contrato).
A32: FALTAN · NORMAS COMPLEMENTARIAS (7)
A33: ley_1676_2013 | B33: Garantías mobiliarias (Ley 1676 de 2013) | C33: ley | D33: Secretaría del Senado | E33: http://www.secretariasenado.gov.co/senado/basedoc/ley_1676_2013.html | F33: falta | G33: media | H33: Garantías sobre bienes muebles.
A34: ley_1996_2019 | B34: Capacidad legal de personas con discapacidad (Ley 1996 de 2019) | C34: ley | D34: Secretaría del Senado | E34: http://www.secretariasenado.gov.co/senado/basedoc/ley_1996_2019.html | F34: falta | G34: media | H34: Capacidad legal y apoyos; modifica el Código Civil (vigencia temporal).
